<sdf version='1.6'>
  <world name='default'>
    <light name='sun' type='directional'>
      <cast_shadows>1</cast_shadows>
      <pose frame=''>0 0 10 0 -0 0</pose>
      <diffuse>0.8 0.8 0.8 1</diffuse>
      <specular>0.2 0.2 0.2 1</specular>
      <attenuation>
        <range>1000</range>
        <constant>0.9</constant>
        <linear>0.01</linear>
        <quadratic>0.001</quadratic>
      </attenuation>
      <direction>-0.5 0.1 -0.9</direction>
    </light>
    <model name='ground_plane'>
      <static>1</static>
      <link name='link'>
        <collision name='collision'>
          <geometry>
            <plane>
              <normal>0 0 1</normal>
              <size>100 100</size>
            </plane>
          </geometry>
          <surface>
            <contact>
              <collide_bitmask>65535</collide_bitmask>
              <ode/>
            </contact>
            <friction>
              <ode>
                <mu>100</mu>
                <mu2>50</mu2>
              </ode>
              <torsional>
                <ode/>
              </torsional>
            </friction>
            <bounce/>
          </surface>
          <max_contacts>10</max_contacts>
        </collision>
        <visual name='visual'>
          <cast_shadows>0</cast_shadows>
          <geometry>
            <plane>
              <normal>0 0 1</normal>
              <size>100 100</size>
            </plane>
          </geometry>
          <material>
            <script>
              <uri>file://media/materials/scripts/gazebo.material</uri>
              <name>Gazebo/Grey</name>
            </script>
          </material>
        </visual>
        <self_collide>0</self_collide>
        <enable_wind>0</enable_wind>
        <kinematic>0</kinematic>
      </link>
    </model>
    <gravity>0 0 -9.8</gravity>
    <magnetic_field>6e-06 2.3e-05 -4.2e-05</magnetic_field>
    <atmosphere type='adiabatic'/>
    <physics name='default_physics' default='0' type='ode'>
      <max_step_size>0.001</max_step_size>
      <real_time_factor>1</real_time_factor>
      <real_time_update_rate>1000</real_time_update_rate>
    </physics>
    <scene>
      <ambient>0.4 0.4 0.4 1</ambient>
      <background>0.7 0.7 0.7 1</background>
      <shadows>1</shadows>
    </scene>
    <audio>
      <device>default</device>
    </audio>
    <wind/>
    <spherical_coordinates>
      <surface_model>EARTH_WGS84</surface_model>
      <latitude_deg>0</latitude_deg>
      <longitude_deg>0</longitude_deg>
      <elevation>0</elevation>
      <heading_deg>0</heading_deg>
    </spherical_coordinates>
    <model name='robot'>
      <link name='base_link'>
        <pose frame=''>0 0 0 0 -0 0</pose>
        <inertial>
          <pose frame=''>-0.0 -0.0 0.0 0 -0 0</pose>
          <mass>40.1703</mass>
          <inertia>
            <ixx>0.0</ixx>
            <ixy>-0.0</ixy>
            <ixz>-0.0</ixz>
            <iyy>0.0</iyy>
            <iyz>0.0</iyz>
            <izz>0.0</izz>
          </inertia>
        </inertial>
        <collision name='base_link_collision'>
          <pose frame=''>0 0 0 0 -0 0</pose>
          <geometry>
            <mesh>
              <scale>1 1 1</scale>
              <uri>/home/tom/probot_g602_ws/src/probot_g602/probot_description/meshes/PROBOT_G602/base_link.STL</uri>
            </mesh>
          </geometry>
          <max_contacts>10</max_contacts>
          <surface>
            <contact>
              <ode/>
            </contact>
            <bounce/>
            <friction>
              <torsional>
                <ode/>
              </torsional>
              <ode/>
            </friction>
          </surface>
        </collision>
        <visual name='base_link_visual'>
          <pose frame=''>0 0 0 0 -0 0</pose>
          <geometry>
            <mesh>
              <scale>1 1 1</scale>
              <uri>/home/tom/probot_g602_ws/src/probot_g602/probot_description/meshes/PROBOT_G602/base_link.STL</uri>
            </mesh>
          </geometry>
        </visual>
        <self_collide>0</self_collide>
        <enable_wind>0</enable_wind>
        <kinematic>0</kinematic>
      </link>
      <link name='link_1'>
        <pose frame=''>0 0 0.17 0 -0 0</pose>
        <inertial>
          <pose frame=''>0.020099 0.000169 0.11023 0 -0 0</pose>
          <mass>2.9125</mass>
          <inertia>
            <ixx>0.023168</ixx>
            <ixy>4.3362e-06</ixy>
            <ixz>-0.0024524</ixz>
            <iyy>0.019701</iyy>
            <iyz>0.0014154</iyz>
            <izz>0.011512</izz>
          </inertia>
        </inertial>
        <collision name='link_1_collision'>
          <pose frame=''>0 0 0 0 -0 0</pose>
          <geometry>
            <mesh>
              <scale>1 1 1</scale>
              <uri>/home/tom/probot_g602_ws/src/probot_g602/probot_description/meshes/PROBOT_G602/link_1.STL</uri>
            </mesh>
          </geometry>
          <max_contacts>10</max_contacts>
          <surface>
            <contact>
              <ode/>
            </contact>
            <bounce/>
            <friction>
              <torsional>
                <ode/>
              </torsional>
              <ode/>
            </friction>
          </surface>
        </collision>
        <visual name='link_1_visual'>
          <pose frame=''>0 0 0 0 -0 0</pose>
          <geometry>
            <mesh>
              <scale>1 1 1</scale>
              <uri>/home/tom/probot_g602_ws/src/probot_g602/probot_description/meshes/PROBOT_G602/link_1.STL</uri>
            </mesh>
          </geometry>
        </visual>
        <self_collide>0</self_collide>
        <enable_wind>0</enable_wind>
        <kinematic>0</kinematic>
      </link>
      <joint name='joint_1' type='revolute'>
        <child>link_1</child>
        <parent>base_link</parent>
        <axis>
          <xyz>0 0 1</xyz>
          <limit>
            <lower>-2.79</lower>
            <upper>2.79</upper>
            <effort>100</effort>
            <velocity>3</velocity>
          </limit>
          <dynamics>
            <spring_reference>0</spring_reference>
            <spring_stiffness>0</spring_stiffness>
          </dynamics>
          <use_parent_model_frame>1</use_parent_model_frame>
        </axis>
      </joint>
      <link name='link_2'>
        <pose frame=''>0.037625 0 0.369 0 -0 0</pose>
        <inertial>
          <pose frame=''>-0.030484 -0.005851 0.11149 0 -0 0</pose>
          <mass>1.37744</mass>
          <inertia>
            <ixx>0.00566218</ixx>
            <ixy>1.46852e-05</ixy>
            <ixz>6.77917e-05</ixz>
            <iyy>0.00818922</iyy>
            <iyz>1.64643e-05</iyz>
            <izz>0.00301091</izz>
          </inertia>
        </inertial>
        <collision name='link_2_collision'>
          <pose frame=''>0 0 0 0 -0 0</pose>
          <geometry>
            <mesh>
              <scale>1 1 1</scale>
              <uri>/home/tom/probot_g602_ws/src/probot_g602/probot_description/meshes/PROBOT_G602/link_2.STL</uri>
            </mesh>
          </geometry>
          <max_contacts>10</max_contacts>
          <surface>
            <contact>
              <ode/>
            </contact>
            <bounce/>
            <friction>
              <torsional>
                <ode/>
              </torsional>
              <ode/>
            </friction>
          </surface>
        </collision>
        <visual name='link_2_visual'>
          <pose frame=''>0 0 0 0 -0 0</pose>
          <geometry>
            <mesh>
              <scale>1 1 1</scale>
              <uri>/home/tom/probot_g602_ws/src/probot_g602/probot_description/meshes/PROBOT_G602/link_2.STL</uri>
            </mesh>
          </geometry>
        </visual>
        <self_collide>0</self_collide>
        <enable_wind>0</enable_wind>
        <kinematic>0</kinematic>
      </link>
      <joint name='joint_2' type='revolute'>
        <child>link_2</child>
        <parent>link_1</parent>
        <axis>
          <xyz>0 -1 0</xyz>
          <limit>
            <lower>-2.37</lower>
            <upper>0.79</upper>
            <effort>100</effort>
            <velocity>3</velocity>
          </limit>
          <dynamics>
            <spring_reference>0</spring_reference>
            <spring_stiffness>0</spring_stiffness>
          </dynamics>
          <use_parent_model_frame>1</use_parent_model_frame>
        </axis>
      </joint>
      <link name='link_3'>
        <pose frame=''>0.037625 0 0.61037 0 -0 0</pose>
        <inertial>
          <pose frame=''>0.005726 0.002896 0.01847 0 -0 0</pose>
          <mass>1.16158</mass>
          <inertia>
            <ixx>0.00245611</ixx>
            <ixy>2.58312e-05</ixy>
            <ixz>-0.000408319</ixz>
            <iyy>0.00325285</iyy>
            <iyz>3.0421e-05</iyz>
            <izz>0.0022872</izz>
          </inertia>
        </inertial>
        <collision name='link_3_collision'>
          <pose frame=''>0 0 0 0 -0 0</pose>
          <geometry>
            <mesh>
              <scale>1 1 1</scale>
              <uri>/home/tom/probot_g602_ws/src/probot_g602/probot_description/meshes/PROBOT_G602/link_3.STL</uri>
            </mesh>
          </geometry>
          <max_contacts>10</max_contacts>
          <surface>
            <contact>
              <ode/>
            </contact>
            <bounce/>
            <friction>
              <torsional>
                <ode/>
              </torsional>
              <ode/>
            </friction>
          </surface>
        </collision>
        <visual name='link_3_visual'>
          <pose frame=''>0 0 0 0 -0 0</pose>
          <geometry>
            <mesh>
              <scale>1 1 1</scale>
              <uri>/home/tom/probot_g602_ws/src/probot_g602/probot_description/meshes/PROBOT_G602/link_3.STL</uri>
            </mesh>
          </geometry>
        </visual>
        <self_collide>0</self_collide>
        <enable_wind>0</enable_wind>
        <kinematic>0</kinematic>
      </link>
      <joint name='joint_3' type='revolute'>
        <child>link_3</child>
        <parent>link_2</parent>
        <axis>
          <xyz>0 -1 0</xyz>
          <limit>
            <lower>-1.27</lower>
            <upper>2.09</upper>
            <effort>100</effort>
            <velocity>3</velocity>
          </limit>
          <dynamics>
            <spring_reference>0</spring_reference>
            <spring_stiffness>0</spring_stiffness>
          </dynamics>
          <use_parent_model_frame>1</use_parent_model_frame>
        </axis>
      </joint>
      <link name='link_4'>
        <pose frame=''>0.117538 0 0.652347 1.5708 -0 1.5708</pose>
        <inertial>
          <pose frame=''>0.003037 0.001559 0.094503 0 -0 0</pose>
          <mass>1.2291</mass>
          <inertia>
            <ixx>0.0038692</ixx>
            <ixy>1.6447e-06</ixy>
            <ixz>-0.00018849</ixz>
            <iyy>0.0036865</iyy>
            <iyz>-2.2864e-05</iyz>
            <izz>0.0013715</izz>
          </inertia>
        </inertial>
        <collision name='link_4_collision'>
          <pose frame=''>0 0 0 0 -0 0</pose>
          <geometry>
            <mesh>
              <scale>1 1 1</scale>
              <uri>/home/tom/probot_g602_ws/src/probot_g602/probot_description/meshes/PROBOT_G602/link_4.STL</uri>
            </mesh>
          </geometry>
          <max_contacts>10</max_contacts>
          <surface>
            <contact>
              <ode/>
            </contact>
            <bounce/>
            <friction>
              <torsional>
                <ode/>
              </torsional>
              <ode/>
            </friction>
          </surface>
        </collision>
        <visual name='link_4_visual'>
          <pose frame=''>0 0 0 0 -0 0</pose>
          <geometry>
            <mesh>
              <scale>1 1 1</scale>
              <uri>/home/tom/probot_g602_ws/src/probot_g602/probot_description/meshes/PROBOT_G602/link_4.STL</uri>
            </mesh>
          </geometry>
        </visual>
        <self_collide>0</self_collide>
        <enable_wind>0</enable_wind>
        <kinematic>0</kinematic>
      </link>
      <joint name='joint_4' type='revolute'>
        <child>link_4</child>
        <parent>link_3</parent>
        <axis>
          <xyz>1 0 -0</xyz>
          <limit>
            <lower>-2.72</lower>
            <upper>2.72</upper>
            <effort>100</effort>
            <velocity>3</velocity>
          </limit>
          <dynamics>
            <spring_reference>0</spring_reference>
            <spring_stiffness>0</spring_stiffness>
          </dynamics>
          <use_parent_model_frame>1</use_parent_model_frame>
        </axis>
      </joint>
      <link name='link_5'>
        <pose frame=''>0.324588 0 0.652347 3.14159 -0 0</pose>
        <inertial>
          <pose frame=''>4e-06 -0.00138 0.031727 0 -0 0</pose>
          <mass>0.66118</mass>
          <inertia>
            <ixx>0.0011184</ixx>
            <ixy>8.7984e-08</ixy>
            <ixz>1.0245e-07</ixz>
            <iyy>0.001172</iyy>
            <iyz>-1.8355e-05</iyz>
            <izz>0.00050623</izz>
          </inertia>
        </inertial>
        <collision name='link_5_collision'>
          <pose frame=''>0 0 0 0 -0 0</pose>
          <geometry>
            <mesh>
              <scale>1 1 1</scale>
              <uri>/home/tom/probot_g602_ws/src/probot_g602/probot_description/meshes/PROBOT_G602/link_5.STL</uri>
            </mesh>
          </geometry>
          <max_contacts>10</max_contacts>
          <surface>
            <contact>
              <ode/>
            </contact>
            <bounce/>
            <friction>
              <torsional>
                <ode/>
              </torsional>
              <ode/>
            </friction>
          </surface>
        </collision>
        <visual name='link_5_visual'>
          <pose frame=''>0 0 0 0 -0 0</pose>
          <geometry>
            <mesh>
              <scale>1 1 1</scale>
              <uri>/home/tom/probot_g602_ws/src/probot_g602/probot_description/meshes/PROBOT_G602/link_5.STL</uri>
            </mesh>
          </geometry>
        </visual>
        <self_collide>0</self_collide>
        <enable_wind>0</enable_wind>
        <kinematic>0</kinematic>
      </link>
      <joint name='joint_5' type='revolute'>
        <child>link_5</child>
        <parent>link_4</parent>
        <axis>
          <xyz>0 -1 0</xyz>
          <limit>
            <lower>-0.44</lower>
            <upper>3.6</upper>
            <effort>100</effort>
            <velocity>3</velocity>
          </limit>
          <dynamics>
            <spring_reference>0</spring_reference>
            <spring_stiffness>0</spring_stiffness>
          </dynamics>
          <use_parent_model_frame>1</use_parent_model_frame>
        </axis>
      </joint>
      <link name='link_6'>
        <pose frame=''>0.324588 -0 0.531847 0 -0 0</pose>
        <inertial>
          <pose frame=''>1e-06 -0 -0.008506 0 -0 0</pose>
          <mass>0.030346</mass>
          <inertia>
            <ixx>7.43293e-06</ixx>
            <ixy>7.2637e-11</ixy>
            <ixz>-7.27933e-10</ixz>
            <iyy>7.43313e-06</iyy>
            <iyz>2.95202e-11</iyz>
            <izz>1.2897e-05</izz>
          </inertia>
        </inertial>
        <collision name='link_6_collision'>
          <pose frame=''>0 0 0 0 -0 0</pose>
          <geometry>
            <mesh>
              <scale>1 1 1</scale>
              <uri>/home/tom/probot_g602_ws/src/probot_g602/probot_description/meshes/PROBOT_G602/link_6.STL</uri>
            </mesh>
          </geometry>
          <max_contacts>10</max_contacts>
          <surface>
            <contact>
              <ode/>
            </contact>
            <bounce/>
            <friction>
              <torsional>
                <ode/>
              </torsional>
              <ode/>
            </friction>
          </surface>
        </collision>
        <collision name='link_6_fixed_joint_lump__camera_link_collision_1'>
          <pose frame=''>0.03 0 -0.06026 1.5 0 1.5</pose>
          <geometry>
            <box>
              <size>0.03 0.03 0.03</size>
            </box>
          </geometry>
          <surface>
            <contact>
              <ode/>
            </contact>
            <friction>
              <ode/>
              <torsional>
                <ode/>
              </torsional>
            </friction>
            <bounce/>
          </surface>
          <max_contacts>10</max_contacts>
        </collision>
        <visual name='link_6_visual'>
          <pose frame=''>0 0 0 0 -0 0</pose>
          <geometry>
            <mesh>
              <scale>1 1 1</scale>
              <uri>/home/tom/probot_g602_ws/src/probot_g602/probot_description/meshes/PROBOT_G602/link_6.STL</uri>
            </mesh>
          </geometry>
        </visual>
        <visual name='link_6_fixed_joint_lump__tool0_visual_1'>
          <pose frame=''>-0.025 0.025 -0.016643 3.14159 -0 0</pose>
          <geometry>
            <mesh>
              <scale>1 1 1</scale>
              <uri>/home/tom/probot_g602_ws/src/probot_g602/probot_description/meshes/PROBOT_G602/tool0.STL</uri>
            </mesh>
          </geometry>
        </visual>
        <visual name='link_6_fixed_joint_lump__camera_link_visual_2'>
          <pose frame=''>0.03 0 -0.06026 0 0 -1.5</pose>
          <geometry>
            <box>
              <size>0.03 0.03 0.03</size>
            </box>
          </geometry>
          <material>
            <script>
              <uri>__default__</uri>
              <name>__default__</name>
            </script>
          </material>
        </visual>
        <gravity>1</gravity>
        <velocity_decay/>
        <sensor name='camera1' type='camera'>
          <update_rate>30</update_rate>
          <camera name='head'>
            <horizontal_fov>1.39626</horizontal_fov>
            <image>
              <width>800</width>
              <height>800</height>
              <format>R8G8B8</format>
            </image>
            <clip>
              <near>0.02</near>
              <far>300</far>
            </clip>
            <noise>
              <type>gaussian</type>
              <mean>0</mean>
              <stddev>0.007</stddev>
            </noise>
          </camera>
          <plugin name='camera_controller' filename='libgazebo_ros_camera.so'>
            <alwaysOn>1</alwaysOn>
            <updateRate>10.0</updateRate>
            <cameraName>usb_cam/camera1</cameraName>
            <imageTopicName>image_raw</imageTopicName>
            <cameraInfoTopicName>camera_info</cameraInfoTopicName>
            <frameName>camera_link</frameName>
            <hackBaseline>0.07</hackBaseline>
            <distortionK1>0.0</distortionK1>
            <distortionK2>0.0</distortionK2>
            <distortionK3>0.0</distortionK3>
            <distortionT1>0.0</distortionT1>
            <distortionT2>0.0</distortionT2>
            <robotNamespace>/</robotNamespace>
          </plugin>
          <pose frame=''>0 0 -0.03026 0 1.5 0</pose>
        </sensor>
        <self_collide>0</self_collide>
        <enable_wind>0</enable_wind>
        <kinematic>0</kinematic>
      </link>
      <joint name='joint_6' type='revolute'>
        <child>link_6</child>
        <parent>link_5</parent>
        <axis>
          <xyz>-0 -0 -1</xyz>
          <limit>
            <lower>-6.26</lower>
            <upper>6.26</upper>
            <effort>100</effort>
            <velocity>3</velocity>
          </limit>
          <dynamics>
            <spring_reference>0</spring_reference>
            <spring_stiffness>0</spring_stiffness>
          </dynamics>
          <use_parent_model_frame>1</use_parent_model_frame>
        </axis>
      </joint>
      <static>0</static>
      <plugin name='gazebo_ros_control' filename='libgazebo_ros_control.so'>
        <robotNamespace>/</robotNamespace>
        <robotSimType>gazebo_ros_control/DefaultRobotHWSim</robotSimType>
        <legacyModeNS>1</legacyModeNS>
      </plugin>
      <pose frame=''>0 0 0 0 -0 0</pose>
    </model>
    <state world_name='default'>
      <sim_time>9 962000000</sim_time>
      <real_time>10 140895325</real_time>
      <wall_time>1640538341 991542799</wall_time>
      <iterations>9962</iterations>
      <model name='flower_pot'>
        <pose frame=''>0.599806 -0.04857 0.002 1.5708 0 -0.004501</pose>
        <scale>1 1 1</scale>
        <link name='link'>
          <pose frame=''>0.599806 -0.04857 0.002 1.5708 0 -0.004501</pose>
          <velocity>0 0 0 0 -0 0</velocity>
          <acceleration>0 0 0 0 -0 0</acceleration>
          <wrench>0 0 0 0 -0 0</wrench>
        </link>
      </model>
      <model name='ground_plane'>
        <pose frame=''>0 0 0 0 -0 0</pose>
        <scale>1 1 1</scale>
        <link name='link'>
          <pose frame=''>0 0 0 0 -0 0</pose>
          <velocity>0 0 0 0 -0 0</velocity>
          <acceleration>0 0 0 0 -0 0</acceleration>
          <wrench>0 0 0 0 -0 0</wrench>
        </link>
      </model>
      <model name='robot'>
        <pose frame=''>0.0 -0.0 -0.0 0.0 -0.0 0.0</pose>
        <scale>1 1 1</scale>
        <link name='base_link'>
          <pose frame=''>0.0 -0.0 -0.0 0.0 -0.0 0.0</pose>
          <velocity>0.0 -0.0 -0.0 0.0 -0.0 0.0</velocity>
          <acceleration>0.0 -0.0 -0.0 -0.0 0.0 -.0</acceleration>
          <wrench>0.0 -0.0 -0.0 0 -0 0</wrench>
        </link>
        <link name='link_1'>
          <pose frame=''>0.002503 -0.001597 0.169999 -3e-06 6e-06 0.026461</pose>
          <velocity>-0.000768 -0.002525 -0.001111 0.012905 -0.007428 0.016778</velocity>
          <acceleration>-1.68076 -2.31707 -2.64476 0.43339 -1.039 1.37956</acceleration>
          <wrench>-4.89522 -6.74846 -7.70287 0 -0 0</wrench>
        </link>
        <link name='link_2'>
          <pose frame=''>0.04012 -0.000599 0.369 -4e-06 9e-06 0.026459</pose>
          <velocity>-0.002156 -0.004759 -0.000829 0.013298 -0.006516 0.016551</velocity>
          <acceleration>-3.17795 -6.59771 -2.95036 1.76644 -1.11166 1.90651</acceleration>
          <wrench>-4.37744 -9.08795 -4.06395 0 -0 0</wrench>
        </link>
        <link name='link_3'>
          <pose frame=''>0.040124 -0.000597 0.610369 -1.5e-05 1.7e-05 0.026468</pose>
          <velocity>-0.003766 -0.007866 -0.000868 0.009942 -0.004087 0.021821</velocity>
          <acceleration>-4.56219 -8.62655 -2.52367 -2.66917 -1.52123 -2.02489</acceleration>
          <wrench>-5.29935 -10.0204 -2.93144 0 -0 0</wrench>
        </link>
        <link name='link_4'>
          <pose frame=''>0.12001 0.00152 0.652341 1.57085 3.7e-05 1.59728</pose>
          <velocity>-0.004004 -0.005826 -0.000646 0.011267 -0.003034 0.031774</velocity>
          <acceleration>-4.85513 -5.73786 -0.908935 1.80788 0.555154 0.770098</acceleration>
          <wrench>-5.96745 -7.0524 -1.11717 0 -0 0</wrench>
        </link>
        <link name='link_5'>
          <pose frame=''>0.326987 0.007002 0.652329 3.14156 5.8e-05 0.02648</pose>
          <velocity>-0.004182 0.001123 1.1e-05 0.012369 -0.00053 0.034506</velocity>
          <acceleration>-4.5476 -2.51674 0.196546 3.11678 -0.083592 1.10985</acceleration>
          <wrench>-3.00678 -1.66402 0.129953 0 -0 0</wrench>
        </link>
        <link name='link_6'>
          <pose frame=''>0.32698 0.006998 0.531829 -3.5e-05 5.9e-05 0.026482</pose>
          <velocity>-0.004116 0.002746 1e-06 0.011795 -0.000529 0.034846</velocity>
          <acceleration>-3.56015 -0.553325 0.188571 2.72184 -0.125656 1.86912</acceleration>
          <wrench>-0.108036 -0.016791 0.005722 0 -0 0</wrench>
        </link>
      </model>
      <model name='unit_sphere'>
        <pose frame=''>0.63166 -0.059966 0.231996 -0.236793 -0.12923 -0.46445</pose>
        <scale>1 1 1</scale>
        <link name='link'>
          <pose frame=''>0.63166 -0.059966 0.231996 -0.236793 -0.12923 -0.46445</pose>
          <velocity>-0.000164 -0.001311 -0.000757 0.109413 -0.012726 -0.001642</velocity>
          <acceleration>-0.001082 -0.007919 -0.009926 0.666871 -0.090768 0</acceleration>
          <wrench>-0.001082 -0.007919 -0.009926 0 -0 0</wrench>
        </link>
      </model>
      <light name='sun'>
        <pose frame=''>0 0 10 0 -0 0</pose>
      </light>
    </state>
    <gui fullscreen='0'>
      <camera name='user_camera'>
        <pose frame=''>-0.553114 1.48795 1.18878 0 0.499642 -0.967813</pose>
        <view_controller>orbit</view_controller>
        <projection_type>perspective</projection_type>
      </camera>
    </gui>
    <model name='flower_pot'>
      <link name='link'>
        <inertial>
          <mass>10</mass>
          <inertia>
            <ixx>0.145833</ixx>
            <ixy>0</ixy>
            <ixz>0</ixz>
            <iyy>0.145833</iyy>
            <iyz>0</iyz>
            <izz>0.125</izz>
          </inertia>
        </inertial>
        <self_collide>0</self_collide>
        <enable_wind>0</enable_wind>
        <kinematic>0</kinematic>
        <pose frame=''>0 0 0 0 -0 0</pose>
        <visual name='visual'>
          <geometry>
            <mesh>
              <scale>1 1 1</scale>
              <uri>/home/tom/probot_g602_ws/src/probot_g602/probot_description/meshes/PROBOT_G602/RobotStation_With flowers.STL</uri>
            </mesh>
          </geometry>
          <material>
            <script>
              <name>Gazebo/Grey</name>
              <uri>file://media/materials/scripts/gazebo.material</uri>
            </script>
          </material>
          <pose frame=''>0 0 0 0 -0 0</pose>
          <transparency>0</transparency>
          <cast_shadows>1</cast_shadows>
        </visual>
        <collision name='collision'>
          <laser_retro>0</laser_retro>
          <max_contacts>10</max_contacts>
          <pose frame=''>0 0 0 0 -0 0</pose>
          <geometry>
            <mesh>
              <uri>/home/tom/probot_g602_ws/src/probot_g602/probot_description/meshes/PROBOT_G602/RobotStation_With flowers.STL</uri>
              <scale>1 1 1</scale>
            </mesh>
          </geometry>
          <surface>
            <friction>
              <ode>
                <mu>1</mu>
                <mu2>1</mu2>
                <fdir1>0 0 0</fdir1>
                <slip1>0</slip1>
                <slip2>0</slip2>
              </ode>
              <torsional>
                <coefficient>1</coefficient>
                <patch_radius>0</patch_radius>
                <surface_radius>0</surface_radius>
                <use_patch_radius>1</use_patch_radius>
                <ode>
                  <slip>0</slip>
                </ode>
              </torsional>
            </friction>
            <bounce>
              <restitution_coefficient>0</restitution_coefficient>
              <threshold>1e+06</threshold>
            </bounce>
            <contact>
              <collide_without_contact>0</collide_without_contact>
              <collide_without_contact_bitmask>1</collide_without_contact_bitmask>
              <collide_bitmask>1</collide_bitmask>
              <ode>
                <soft_cfm>0</soft_cfm>
                <soft_erp>0.2</soft_erp>
                <kp>1e+13</kp>
                <kd>1</kd>
                <max_vel>0.01</max_vel>
                <min_depth>0</min_depth>
              </ode>
              <bullet>
                <split_impulse>1</split_impulse>
                <split_impulse_penetration_threshold>-0.01</split_impulse_penetration_threshold>
                <soft_cfm>0</soft_cfm>
                <soft_erp>0.2</soft_erp>
                <kp>1e+13</kp>
                <kd>1</kd>
              </bullet>
            </contact>
          </surface>
        </collision>
      </link>
      <static>1</static>
      <allow_auto_disable>1</allow_auto_disable>
      <pose frame=''>0.599806 -0.04857 0.002 1.5708 0 -0.004501</pose>
    </model>
    <model name='unit_sphere'>
      <link name='link'>
        <inertial>
          <mass>1</mass>
          <inertia>
            <ixx>0.1</ixx>
            <ixy>0</ixy>
            <ixz>0</ixz>
            <iyy>0.1</iyy>
            <iyz>0</iyz>
            <izz>0.1</izz>
          </inertia>
        </inertial>
        <self_collide>0</self_collide>
        <enable_wind>0</enable_wind>
        <kinematic>0</kinematic>
        <pose frame=''>0 0 0 0 -0 0</pose>
        <visual name='visual'>
          <geometry>
            <sphere>
              <radius>0.0138318</radius>
            </sphere>
          </geometry>
          <material>
            <script>
              <name>Gazebo/Red</name>
              <uri>file://media/materials/scripts/gazebo.material</uri>
            </script>
          </material>
          <pose frame=''>0 0 0 0 -0 0</pose>
          <transparency>0</transparency>
          <cast_shadows>1</cast_shadows>
        </visual>
        <collision name='collision'>
          <laser_retro>0</laser_retro>
          <max_contacts>10</max_contacts>
          <pose frame=''>0 0 0 0 -0 0</pose>
          <geometry>
            <sphere>
              <radius>0.013832</radius>
            </sphere>
          </geometry>
          <surface>
            <friction>
              <ode>
                <mu>1</mu>
                <mu2>1</mu2>
                <fdir1>0 0 0</fdir1>
                <slip1>0</slip1>
                <slip2>0</slip2>
              </ode>
              <torsional>
                <coefficient>1</coefficient>
                <patch_radius>0</patch_radius>
                <surface_radius>0</surface_radius>
                <use_patch_radius>1</use_patch_radius>
                <ode>
                  <slip>0</slip>
                </ode>
              </torsional>
            </friction>
            <bounce>
              <restitution_coefficient>0</restitution_coefficient>
              <threshold>1e+06</threshold>
            </bounce>
            <contact>
              <collide_without_contact>0</collide_without_contact>
              <collide_without_contact_bitmask>1</collide_without_contact_bitmask>
              <collide_bitmask>1</collide_bitmask>
              <ode>
                <soft_cfm>0</soft_cfm>
                <soft_erp>0.2</soft_erp>
                <kp>1e+13</kp>
                <kd>1</kd>
                <max_vel>0.01</max_vel>
                <min_depth>0</min_depth>
              </ode>
              <bullet>
                <split_impulse>1</split_impulse>
                <split_impulse_penetration_threshold>-0.01</split_impulse_penetration_threshold>
                <soft_cfm>0</soft_cfm>
                <soft_erp>0.2</soft_erp>
                <kp>1e+13</kp>
                <kd>1</kd>
              </bullet>
            </contact>
          </surface>
        </collision>
      </link>
      <static>0</static>
      <allow_auto_disable>1</allow_auto_disable>
      <pose frame=''>0.631589 -0.059693 0.232132 -0.05717 -0.350174 -0.503565</pose>
    </model>
  </world>
</sdf>
